# 输出数据

输出数据指的是返回**成功**结果或**失败**的信息，在之前的章节中你已经看到了如何输出一个结果，直接在控制器中 `return` 结果即可，
但是需要注意的是，如果使用空 `return` 或者不 `return` 将会得到一个 404 状态码，除非之前给 `ctx.body` 设置了值。

输出的结果结构本身是可以被再次包装的，配置 resutl 模块的 success 方法即可。

```ts
import { mapping, Context } from 'zenweb';

export class TestController {
  @mapping()
  test1() {
    return 'OK'; // 客户端将会得到 { data: 'OK' }
  }

  @mapping()
  test2() {
    // 不做任何返回，客户端将会得到一个 404 错误状态
  }

  @mapping()
  test3(ctx: Context) {
    ctx.success('OK'); // 也可以使用 success 方法返回结果
    ctx.success('NOT OK'); // 但是需要注意的是，success 方法并不会结束执行，后续再次调用会覆盖之前的结果
    // ctx.success 方法本质上就是给 ctx.body 设值，只是多了一层结果包装
  }
}
```

对于错误输出，我们推荐使用 `ctx.fail` 功能来统一错误信息。

这样做的好处有：
- 可以直接终止当前代码执行
- 可以统一错误消息
- 统一管理错误代码，防止重复定义相同的代码

在使用 `ctx.fail` 功能之前我们应该配置一下 `message-codes.json` 文件，来统一定义错误信息。

```json title="message-codes.json"
{
  "100": "这是一个绝对值的错误信息",
  "user.register": "带有递归回退的错误匹配",
  "user.register.username.empty": "这是一个带有标签命名的错误信息",
  "user.register.username.short": "你的用户名太短了，当前用户名 {username} 长度只有 {currentLength}，需要长度 {minLength}"
}
```

```ts
import { mapping, Context, ResultFail } from 'zenweb';

export class TestController {
  @mapping()
  test1(ctx: Context) {
    ctx.fail(100);
  }

  @mapping()
  test2(ctx: Context) {
    ctx.fail('user.register.username.empty');
  }

  @mapping()
  test3(ctx: Context) {
    ctx.fail('user.register.username.short', {
      username: 'Bob',
      currentLength: 3,
      minLength: 4,
    });
  }

  @mapping()
  test4(ctx: Context) {
    ctx.fail('user.register.other');
    // 这里的 user.register.other 并没有配置在 message-codes.json 中，但是依然可以输出错误信息 “带有递归回退的错误匹配”
  }

  @mapping()
  test5(ctx: Context) {
    throw new ResultFail({
      code: 123,
      message: '也可以直接抛出异常对象',
    });
  }
}
```
